 URL : "https://github.com/pettazz/pygooglevoice/issues/46" TITLE : issue with login BODY : pulling from the newest version of the repository 41 , i'm the code is raising a login error. this is what i have written: from googlevoice import voice from googlevoice.util import input import beautifulsoup username, password = xxxx@gmail.com , xxxxxx ...... def google_login username, password : voice = voice client = voice.login username, password print client return client however, i'm getting this error: traceback most recent call last : file e:/jason core/boot.py , line 75, in <module> control file e:/jason core/boot.py , line 70, in control logins = system_logins.read_logins basedir file e:\jason core\system_logins.py , line 33, in read_logins gv = google_login login_list type_list.index item , password_list type_list.index item file e:\jason core\system_logins.py , line 44, in google_login client = voice.login username, password file c:\python27\lib\site-packages\googlevoice\voice.py , line 94, in login raise loginerror