 URL : "https://github.com/coblo/gui-demo/issues/96" TITLE : error in logfile. BODY : tried to revoke access without having the permission. but not sure if the reason was another.. having the db open in an editor gui behave fine. only an error in the logfile. ceback most recent call last : file /home/flo/.pyenv/versions/3.5.3/lib/python3.5/site-packages/peewee.py , line 3830, in execute_sql cursor.execute sql, params or sqlite3.operationalerror: database is locked during handling of the above exception, another exception occurred: traceback most recent call last : file /home/flo/coblo/gui-demo/app/widgets/community_tables.py , line 82, in data last_voted = perm_obj.address.get_last_voted file /home/flo/coblo/gui-demo/app/models/address.py , line 48, in get_last_voted latest_vote = self.votes_given.order_by vote.time.desc .first file /home/flo/.pyenv/versions/3.5.3/lib/python3.5/site-packages/peewee.py , line 3237, in first return self.peek n=n file /home/flo/.pyenv/versions/3.5.3/lib/python3.5/site-packages/peewee.py , line 3227, in peek