 URL : "https://github.com/yunjey/show-attend-and-tell/issues/26" TITLE : ioerror in train.py BODY : when i run train.py,i got the problem says traceback most recent call last : file train.py , line 25, in <module> main file train.py , line 8, in main data = load_coco_data data_path='./data', split='train' file /home/sxm/bishe/tensorflow-git/show-attend-and-tell-tensorflow/core/utils.py , line 13, in load_coco_data data 'features' = hickle.load os.path.join data_path, '%s.features.hkl' %split file /home/sxm/tensorflow/local/lib/python2.7/site-packages/hickle.py , line 616, in load h5f = file_opener fileobj file /home/sxm/tensorflow/local/lib/python2.7/site-packages/hickle.py , line 154, in file_opener h5f = h5.file filename, mode file /usr/lib/python2.7/dist-packages/h5py/_hl/files.py , line 207, in __init__ fid = make_fid name, mode, userblock_size, fapl file /usr/lib/python2.7/dist-packages/h5py/_hl/files.py , line 79, in make_fid fid = h5f.open name, h5f.acc_rdonly, fapl=fapl file h5f.pyx , line 71, in h5py.h5f.open h5py/h5f.c:1806 ioerror: unable to open file file accessibilty: unable to open file is there anybody has the same problem?i don't know how to fix it...