 URL : "https://github.com/herooutoftime/ajenti-letsencrypt/issues/8" TITLE : request not working BODY : errno 2 no such file or directory traceback most recent call last : file /usr/lib/pymodules/python2.7/ajenti/plugins/main/main.py , line 158, in handle_message self.ui.dispatch_event update 'uid' , update 'event' , update 'params' file /usr/lib/pymodules/python2.7/ajenti/ui/__init__.py , line 72, in dispatch_event self.root.dispatch_event uid, event, params file /usr/lib/pymodules/python2.7/ajenti/ui/element.py , line 382, in dispatch_event if child.dispatch_event uid, event, params : file /usr/lib/pymodules/python2.7/ajenti/ui/element.py , line 382, in dispatch_event if child.dispatch_event uid, event, params : file /usr/lib/pymodules/python2.7/ajenti/ui/element.py , line 388, in dispatch_event getattr self, k params or {} file /var/lib/ajenti/plugins/letsencrypt/main.py , line 230, in request_button self.request_certificates file /var/lib/ajenti/plugins/letsencrypt/main.py , line 198, in request_certificates p = subprocess.popen params, stdout=subprocess.pipe, stderr=subprocess.pipe file /usr/lib/pymodules/python2.7/ajenti/compat.py , line 26, in popen args, kwargs file /usr/lib/python2.7/dist-packages/gevent/subprocess.py , line 238, in __init__ errread, errwrite file /usr/lib/python2.7/dist-packages/gevent/subprocess.py , line 755, in _execute_child raise child_exception oserror: errno 2 no such file or directory