 URL : "https://github.com/certtools/intelmq/issues/1035" TITLE : vxvault parser error BODY : the vxvault parser was giving me the following error: 2017-07-05 15:01:17,325 - vxvault-parser - error - failed to parse line. traceback most recent call last : file /usr/lib/python3.4/site-packages/intelmq/lib/bot.py , line 643, in process events = list filter bool, self.parse_line line, report file /usr/lib/python3.4/site-packages/intelmq/bots/parsers/vxvault/parser.py , line 39, in parse_line event.add time.source , self.tempdata 1 file /usr/lib/python3.4/site-packages/intelmq/lib/message.py , line 205, in add raise exceptions.invalidvalue key, old_value intelmq.lib.exceptions.invalidvalue: invalid value 'vx vault last 100 links' <class 'str'> for key 'time.source' i downloaded the report from http://vxvault.net/url_list.php url using wget and when i opened it, i saw that it has an extra line: <pre> vx vault last 100 links wed, 05 jul 2017 14:12:27 +0000 http://stomkgmu.ru/wstat/svchost.exe http://dtechgroup.com/r6.php?cmd=e http://fortuma.co/scu.exe http://lucabartoleschi.it/r6.php?cmd=e http://exploitoru.us/anyi.jpg ... so the code of the script for the vxvault parser must be updated, lines 12 and 13: self.tempdata = report_split :2 for line in report_split 3: : should be changed to: self.tempdata = report_split :3 for line in report_split 4: : and also the line 39: event.add time.source , self.tempdata 1 should be changed to: event.add time.source , self.tempdata 2