 URL : "https://github.com/GoogleCloudPlatform/google-cloud-python/issues/2980" TITLE : bigtable invalidchunk BODY : 1. os type and version ubuntu 14.04 2. python version and virtual environment information python --version python 2.7.6 3. google-cloud-python version pip show google-cloud , pip show google-<service> or pip freeze name: google-cloud-bigtable version: 0.22.0 4. stacktrace if available traceback most recent call last : file bt.py , line 13, in <module> row = bt_table.read_row '166657957cd9d730abe8f5f73bcfecda' file /home/jungho.ahn/tmp/test/local/lib/python2.7/site-packages/google/cloud/bigtable/table.py , line 234, in read_row rows_data.consume_all file /home/jungho.ahn/tmp/test/local/lib/python2.7/site-packages/google/cloud/bigtable/row_data.py , line 323, in consume_all self.consume_next file /home/jungho.ahn/tmp/test/local/lib/python2.7/site-packages/google/cloud/bigtable/row_data.py , line 275, in consume_next self._validate_chunk chunk file /home/jungho.ahn/tmp/test/local/lib/python2.7/site-packages/google/cloud/bigtable/row_data.py , line 390, in _validate_chunk self._validate_chunk_row_in_progress chunk file /home/jungho.ahn/tmp/test/local/lib/python2.7/site-packages/google/cloud/bigtable/row_data.py , line 370, in _validate_chunk_row_in_progress _raise_if not chunk.timestamp_micros or not chunk.value file /home/jungho.ahn/tmp/test/local/lib/python2.7/site-packages/google/cloud/bigtable/row_data.py , line 441, in _raise_if raise invalidchunk args google.cloud.bigtable.row_data.invalidchunk 5. steps to reproduce see the code example 6. code example from google.cloud import bigtable bt_client = bigtable.client.client project='myproject', read_only=true bt_instance = bt_client.instance instance_id='myinstance' bt_table = bt_instance.table table_id='mytable' row = bt_table.read_row 'mykey' print row.cells this exception is raised all the time. did i use incorrectly? thanks,