 URL : "https://github.com/imageio/imageio/issues/235" TITLE : ffmpeg read_infos bug BODY : hi, i just found a bug in the ffmpeg plugin that results in the following traceback: traceback most recent call last : file c:/users/felix/pycharmprojects/imageio/test.py , line 9, in <module> vid = imageio.get_reader filename, 'ffmpeg', ffmpeg_params= '-loglevel', 'fatal', '-err_detect', 'aggressive' file c:\users\felix\pycharmprojects\imageio\imageio\core\functions.py , line 111, in get_reader return format.get_reader request file c:\users\felix\pycharmprojects\imageio\imageio\core\format.py , line 169, in get_reader return self.reader self, request file c:\users\felix\pycharmprojects\imageio\imageio\core\format.py , line 218, in __init__ self._open self.request.kwargs.copy file c:\users\felix\pycharmprojects\imageio\imageio\plugins\ffmpeg.py , line 306, in _open self._load_infos file c:\users\felix\pycharmprojects\imageio\imageio\plugins\ffmpeg.py , line 445, in _load_infos self._terminate file c:\users\felix\pycharmprojects\imageio\imageio\plugins\ffmpeg.py , line 430, in _terminate if self._frame_catcher: attributeerror: 'reader' object has no attribute '_frame_catcher' this happens if the ffmpeg process doesn't print anything to stderr. the problem is that self._frame_catcher is initialized after the call to self._load_infos which in case of an error calls self._terminate which then accesses self._frame_catcher . you can reproduce the bug by using the code changes from 234 and passing ffmpeg_params= '-loglevel', 'fatal' to the reader.