 URL : "https://github.com/worawit/MS17-010/issues/13" TITLE : typerror on mysmb.py. BODY : hello, when i run the checker.py, i get an error from mysmb.py: bash root@kali:~/documents/eternalblue python checker.py 10.0.0.9 target os: traceback most recent call last : file checker.py , line 42, in <module> conn.login username, password file /root/documents/labs/218/mysmb.py , line 152, in login smb.smb.login self, user, password, domain, lmhash, nthash, ntlm_fallback typeerror: login takes at most 6 arguments 7 given is this an error? or do i have to give checker.py more/less input?