 URL : "https://github.com/mcleung/PyAPT/issues/5" TITLE : go_home function error BODY : i came across an error with the go_home function. the problem is that when go_home function is executed the program crashes with the following error message: c:\pyapt.pyc in go_home self 292 raise exception 'please connect first! use initializehardwaredevice' 293 if self.verbose: print 'go_home sucess' --> 294 self.aptdll.mot_movehome self.serialnum 295 return true 296 any suggestion on how to solve this issue?