 URL : "https://github.com/jaredhanson/passport-instagram/issues/11" TITLE : oautherror on callback BODY : hi, i'm getting the following error when landing back on my /auth/ig/callback: error at strategy.oauth2strategy._createoautherror /users/jack/code/fiiture/node_modules/passport-oauth2/lib/strategy.js:379:17 at /users/jack/code/fiiture/node_modules/passport-oauth2/lib/strategy.js:166:45 at /users/jack/code/fiiture/node_modules/oauth/lib/oauth2.js:191:18 at passbackcontrol /users/jack/code/fiiture/node_modules/oauth/lib/oauth2.js:132:9 at incomingmessage.<anonymous> /users/jack/code/fiiture/node_modules/oauth/lib/oauth2.js:157:7 at emitnone events.js:91:20 at incomingmessage.emit events.js:185:7 at endreadablent _stream_readable.js:974:12 at _combinedtickcallback internal/process/next_tick.js:74:11 at process._tickdomaincallback internal/process/next_tick.js:122:9 the code driving my implementation is: passport.use new instagramstrategy { clientid: cfg.instagram_api_clientid, clientsecret: cfg.instagram_api_clientsecret, callbackurl: cfg.instagram_api_authcallback }, accesstoken, refreshtoken, profile, done => { // i don't get here console.log profile console.log refreshtoken console.log accesstoken done null, profile } app.get '/auth/ig', passport.authenticate 'instagram' app.get '/auth/ig/callback', req, res, next => { // i get here log callback next }, passport.authenticate 'instagram', { failureredirect: '/auth/ig' } , req, res => { res.redirect '/' } callback is logged but then the failure happens. none of profile, refreshtoken or accesstoken are logged. in browser, i land as i would expect on /auth/ig/callback?code=accesscodenfjnejeneakjv . this error's really impenetrable - any guesses as to what's going wrong here?