 URL : "https://github.com/PyFilesystem/pyfilesystem2/issues/79" TITLE : update six requirement BODY : pyfilesystem2 requires six version 1.10. in setup.py : six~=1.10.0 is this a hard requirement? version 1.11.0 of six has just been released and we've been hitting the following error ever since, when setting up our testing infrastructure: python traceback most recent call last : file .tox/py34/lib/python3.4/site-packages/_pytest/vendored_packages/pluggy.py , line 510, in load_setuptools_entrypoints plugin = ep.load file .tox/py34/lib/python3.4/site-packages/pkg_resources/__init__.py , line 2404, in load self.require args, kwargs file .tox/py34/lib/python3.4/site-packages/pkg_resources/__init__.py , line 2427, in require items = working_set.resolve reqs, env, installer, extras=self.extras file .tox/py34/lib/python3.4/site-packages/pkg_resources/__init__.py , line 872, in resolve raise versionconflict dist, req .with_context dependent_req pkg_resources.contextualversionconflict: six 1.11.0 .tox/py34/lib/python3.4/site-packages , requirement.parse 'six~=1.10.0' , {'fs'} i'm not able to currently pinpoint the issue to provide you with a test , but i can fix the problem by pinning six to 1.10.0 . in some sense this is a pip issue, but since pyfilesystem2 limits six to 1.10. it's only a matter of time until it is incompatible with some other package that'll require 1.11.0+ . could the requirement maybe be changed to six>=1.10.0 ?