 URL : "https://github.com/wandb/client/issues/91" TITLE : strange error in my log BODY : in run https://app.wandb.ai/l2k2/imagenet/runs/lzwxja31 i get an error: epoch: 0 3100/5005 time 1.292 1.314 data 0.001 0.009 loss 5.4356 6.2212 prec@1 4.297 2.134 prec@5 14.062 6.970 exception in thread thread-24876: traceback most recent call last : file /home/ubuntu/.pyenv/versions/anaconda3-5.0.1/lib/python3.6/site-packages/wandb/api.py , line 69, in wrapper return func args, kwargs file /home/ubuntu/.pyenv/versions/anaconda3-5.0.1/lib/python3.6/site-packages/wandb/api.py , line 501, in upload_urls 'files': file for file in files file /home/ubuntu/.pyenv/versions/anaconda3-5.0.1/lib/python3.6/site-packages/gql/client.py , line 52, in execute raise exception str result.errors 0 exception: {'message': 'the api call urlfetch.fetch took too long to respond and was cancelled.', 'code': 500, 'locations': {'column': 13, 'line': 9} } during handling of the above exception, another exception occurred: traceback most recent call last : file /home/ubuntu/.pyenv/versions/anaconda3-5.0.1/lib/python3.6/site-packages/wandb/api.py , line 69, in wrapper return func args, kwargs file /home/ubuntu/.pyenv/versions/anaconda3-5.0.1/lib/python3.6/site-packages/wandb/api.py , line 657, in push