 URL : "https://github.com/jotyGill/openpyn-nordvpn/issues/64" TITLE : area connect not possible BODY : hey, if i use for example openpyn us -a ny i got this output: traceback most recent call last : file /usr/local/bin/openpyn , line 9, in <module> load_entry_point 'openpyn==1.7.3', 'console_scripts', 'openpyn' file /usr/local/lib/python3.4/dist-packages/openpyn-1.7.3-py3.4.egg/openpyn/openpyn.py , line 116, in main args.skip_dns_patch file /usr/local/lib/python3.4/dist-packages/openpyn-1.7.3-py3.4.egg/openpyn/openpyn.py , line 191, in run dedicated, double_vpn, tor_over_vpn, anti_ddos file /usr/local/lib/python3.4/dist-packages/openpyn-1.7.3-py3.4.egg/openpyn/openpyn.py , line 293, in find_better_servers double_vpn=double_vpn, tor_over_vpn=tor_over_vpn, anti_ddos=anti_ddos file /usr/local/lib/python3.4/dist-packages/openpyn-1.7.3-py3.4.egg/openpyn/openpyn.py , line 276, in get_data_from_api type_country_area_filtered = filters.filter_by_area area, type_country_filtered file /usr/local/lib/python3.4/dist-packages/openpyn-1.7.3-py3.4.egg/openpyn/filters.py , line 8, in filter_by_area resolved_locations = locations.get_unique_locations list_of_servers=type_country_filtered file /usr/local/lib/python3.4/dist-packages/openpyn-1.7.3-py3.4.egg/openpyn/locations.py , line 14, in get_unique_locations geo_address_list = get_location_name eachlocation file /usr/local/lib/python3.4/dist-packages/openpyn-1.7.3-py3.4.egg/openpyn/locations.py , line 34, in get_location_name results = r.json 'results' 0 'address_components' indexerror: list index out of range connection with country only is no problem.